<?xml version="1.0"?>

<robot name="humblebot">

    <material name="green">
        <color rgba="0 1 0 1" />
    </material>

    <link name="base_link">
        <visual>
            <geometry>
                <cylinder radius="0.24" length="0.08" />
            </geometry>
            <origin xyz="0 0 0.04" rpy="0 0 0" />
            <material name="green" />
        </visual>
    </link>

    <link name="wheel_60deg">
        <visual>
            <geometry>
                <cylinder radius="0.07" length="0.03" />
            </geometry>
            <origin xyz="0 0 0.015" rpy="0 0 0" />
            <material name="green" />
        </visual>
    </link>

    <link name="wheel_240deg">
        <visual>
            <geometry>
                <cylinder radius="0.07" length="0.03" />
            </geometry>
            <origin xyz="0 0 -0.015" rpy="0 0 0" />
            <material name="green" />
        </visual>
    </link>

    <joint name="base_wheel60_joint" type="continuous">
        <parent link="base_link" />
        <child link="wheel_60deg" />
        <axis xyz="0 0 1" />
        <origin xyz="0.207 0.120 0" rpy="0 1.57 0.52" />
    </joint>

    <joint name="base_wheel240_joint" type="continuous">
        <parent link="base_link" />
        <child link="wheel_240deg" />
        <axis xyz="0 0 1" />
        <origin xyz="-0.207 0.120 0" rpy="0 1.57 -0.52" />
    </joint>

</robot>