<?xml version="1.0" ?>
<!-- =================================================================================== -->
<!-- |    This document was autogenerated by xacro from humblebot.xacro                | -->
<!-- |    EDITING THIS FILE BY HAND IS NOT RECOMMENDED                                 | -->
<!-- =================================================================================== -->
<robot name="humblebot">
  <material name="green">
    <color rgba="0 1 0 1"/>
  </material>
  <material name="black">
    <color rgba="0 0 0 1"/>
  </material>
  <link name="base_footprint"/>
  <link name="base_link">
    <visual>
      <geometry>
        <cylinder length="0.08" radius="0.12"/>
      </geometry>
      <origin rpy="0 0 0" xyz="0 0 0.04"/>
      <material name="green"/>
    </visual>
  </link>
  <!--Wheel 60deg-->
  <link name="wheel_60deg">
    <visual>
      <geometry>
        <cylinder length="0.03" radius="0.035"/>
      </geometry>
      <origin rpy="0 0 0" xyz="0 0 0.015"/>
      <material name="green"/>
    </visual>
  </link>
  <link name="wheel_60deg_roller_1">
    <visual>
      <geometry>
        <cylinder length="0.022" radius="0.0075"/>
      </geometry>
      <origin rpy="0 0 0" xyz="0 0 0"/>
      <material name="black"/>
    </visual>
  </link>
  <link name="wheel_60deg_roller_2">
    <visual>
      <geometry>
        <cylinder length="0.022" radius="0.0075"/>
      </geometry>
      <origin rpy="0 0 0" xyz="0 0 0"/>
      <material name="black"/>
    </visual>
  </link>
  <link name="wheel_60deg_roller_3">
    <visual>
      <geometry>
        <cylinder length="0.022" radius="0.0075"/>
      </geometry>
      <origin rpy="0 0 0" xyz="0 0 0"/>
      <material name="black"/>
    </visual>
  </link>
  <link name="wheel_60deg_roller_4">
    <visual>
      <geometry>
        <cylinder length="0.022" radius="0.0075"/>
      </geometry>
      <origin rpy="0 0 0" xyz="0 0 0"/>
      <material name="black"/>
    </visual>
  </link>
  <link name="wheel_60deg_roller_5">
    <visual>
      <geometry>
        <cylinder length="0.022" radius="0.0075"/>
      </geometry>
      <origin rpy="0 0 0" xyz="0 0 0"/>
      <material name="black"/>
    </visual>
  </link>
  <link name="wheel_60deg_roller_6">
    <visual>
      <geometry>
        <cylinder length="0.022" radius="0.0075"/>
      </geometry>
      <origin rpy="0 0 0" xyz="0 0 0"/>
      <material name="black"/>
    </visual>
  </link>
  <link name="wheel_60deg_roller_7">
    <visual>
      <geometry>
        <cylinder length="0.022" radius="0.0075"/>
      </geometry>
      <origin rpy="0 0 0" xyz="0 0 0"/>
      <material name="black"/>
    </visual>
  </link>
  <link name="wheel_60deg_roller_8">
    <visual>
      <geometry>
        <cylinder length="0.022" radius="0.0075"/>
      </geometry>
      <origin rpy="0 0 0" xyz="0 0 0"/>
      <material name="black"/>
    </visual>
  </link>
  <link name="wheel_60deg_roller_9">
    <visual>
      <geometry>
        <cylinder length="0.022" radius="0.0075"/>
      </geometry>
      <origin rpy="0 0 0" xyz="0 0 0"/>
      <material name="black"/>
    </visual>
  </link>
  <link name="wheel_60deg_roller_10">
    <visual>
      <geometry>
        <cylinder length="0.022" radius="0.0075"/>
      </geometry>
      <origin rpy="0 0 0" xyz="0 0 0"/>
      <material name="black"/>
    </visual>
  </link>
  <link name="wheel_60deg_roller_11">
    <visual>
      <geometry>
        <cylinder length="0.022" radius="0.0075"/>
      </geometry>
      <origin rpy="0 0 0" xyz="0 0 0"/>
      <material name="black"/>
    </visual>
  </link>
  <link name="wheel_60deg_roller_12">
    <visual>
      <geometry>
        <cylinder length="0.022" radius="0.0075"/>
      </geometry>
      <origin rpy="0 0 0" xyz="0 0 0"/>
      <material name="black"/>
    </visual>
  </link>
  <joint name="base_joint" type="fixed">
    <parent link="base_footprint"/>
    <child link="base_link"/>
    <origin rpy="0 0 0" xyz="0 0 0.035"/>
  </joint>
  <joint name="base_wheel60_joint" type="continuous">
    <parent link="base_link"/>
    <child link="wheel_60deg"/>
    <axis xyz="0 0 1"/>
    <origin rpy="-1.0471975511965976 1.5707963267948966 0" xyz="0.06 0.10392304845413262 0"/>
  </joint>
  <joint name="wheel_60deg_roller_1" type="continuous">
    <parent link="wheel_60deg"/>
    <child link="wheel_60deg_roller_1"/>
    <axis xyz="0 0 1"/>
    <origin rpy="1.5707963267948966 0 0" xyz="0.035 0 0"/>
  </joint>
  <joint name="wheel_60deg_roller_2" type="continuous">
    <parent link="wheel_60deg"/>
    <child link="wheel_60deg_roller_2"/>
    <axis xyz="0 0 1"/>
    <origin rpy="1.5707963267948966 0 0" xyz="-0.035 0 0"/>
  </joint>
  <joint name="wheel_60deg_roller_3" type="continuous">
    <parent link="wheel_60deg"/>
    <child link="wheel_60deg_roller_3"/>
    <axis xyz="0 0 1"/>
    <origin rpy="1.5707963267948966 0 -1.0471975511965976" xyz="-0.0175 0.03 0"/>
  </joint>
  <joint name="wheel_60deg_roller_4" type="continuous">
    <parent link="wheel_60deg"/>
    <child link="wheel_60deg_roller_4"/>
    <axis xyz="0 0 1"/>
    <origin rpy="1.5707963267948966 0 -1.0471975511965976" xyz="0.0175 -0.03 0"/>
  </joint>
  <joint name="wheel_60deg_roller_5" type="continuous">
    <parent link="wheel_60deg"/>
    <child link="wheel_60deg_roller_5"/>
    <axis xyz="0 0 1"/>
    <origin rpy="1.5707963267948966 0 1.0471975511965976" xyz="-0.0175 -0.03 0"/>
  </joint>
  <joint name="wheel_60deg_roller_6" type="continuous">
    <parent link="wheel_60deg"/>
    <child link="wheel_60deg_roller_6"/>
    <axis xyz="0 0 1"/>
    <origin rpy="1.5707963267948966 0 1.0471975511965976" xyz="0.0175 0.03 0"/>
  </joint>
  <joint name="wheel_60deg_roller_7" type="continuous">
    <parent link="wheel_60deg"/>
    <child link="wheel_60deg_roller_7"/>
    <axis xyz="0 0 1"/>
    <origin rpy="1.5707963267948966 0 1.5707963267948966" xyz="0 0.035 0.03"/>
  </joint>
  <joint name="wheel_60deg_roller_8" type="continuous">
    <parent link="wheel_60deg"/>
    <child link="wheel_60deg_roller_8"/>
    <axis xyz="0 0 1"/>
    <origin rpy="1.5707963267948966 0 1.5707963267948966" xyz="0 -0.035 0.03"/>
  </joint>
  <joint name="wheel_60deg_roller_9" type="continuous">
    <parent link="wheel_60deg"/>
    <child link="wheel_60deg_roller_9"/>
    <axis xyz="0 0 1"/>
    <origin rpy="1.5707963267948966 0 0.57" xyz="-0.03 -0.0175 0.03"/>
  </joint>
  <joint name="wheel_60deg_roller_10" type="continuous">
    <parent link="wheel_60deg"/>
    <child link="wheel_60deg_roller_10"/>
    <axis xyz="0 0 1"/>
    <origin rpy="1.5707963267948966 0 0.57" xyz="0.03 0.0175 0.03"/>
  </joint>
  <joint name="wheel_60deg_roller_11" type="continuous">
    <parent link="wheel_60deg"/>
    <child link="wheel_60deg_roller_11"/>
    <axis xyz="0 0 1"/>
    <origin rpy="1.5707963267948966 0 -0.57" xyz="-0.03 0.0175 0.03"/>
  </joint>
  <joint name="wheel_60deg_roller_12" type="continuous">
    <parent link="wheel_60deg"/>
    <child link="wheel_60deg_roller_12"/>
    <axis xyz="0 0 1"/>
    <origin rpy="1.5707963267948966 0 -0.57" xyz="0.03 -0.0175 0.03"/>
  </joint>
  <!--Wheel 300deg-->
  <link name="wheel_300deg">
    <visual>
      <geometry>
        <cylinder length="0.03" radius="0.035"/>
      </geometry>
      <origin rpy="0 0 0" xyz="0 0 0.015"/>
      <material name="green"/>
    </visual>
  </link>
  <link name="wheel_300deg_roller_1">
    <visual>
      <geometry>
        <cylinder length="0.022" radius="0.0075"/>
      </geometry>
      <origin rpy="0 0 0" xyz="0 0 0"/>
      <material name="black"/>
    </visual>
  </link>
  <link name="wheel_300deg_roller_2">
    <visual>
      <geometry>
        <cylinder length="0.022" radius="0.0075"/>
      </geometry>
      <origin rpy="0 0 0" xyz="0 0 0"/>
      <material name="black"/>
    </visual>
  </link>
  <link name="wheel_300deg_roller_3">
    <visual>
      <geometry>
        <cylinder length="0.022" radius="0.0075"/>
      </geometry>
      <origin rpy="0 0 0" xyz="0 0 0"/>
      <material name="black"/>
    </visual>
  </link>
  <link name="wheel_300deg_roller_4">
    <visual>
      <geometry>
        <cylinder length="0.022" radius="0.0075"/>
      </geometry>
      <origin rpy="0 0 0" xyz="0 0 0"/>
      <material name="black"/>
    </visual>
  </link>
  <link name="wheel_300deg_roller_5">
    <visual>
      <geometry>
        <cylinder length="0.022" radius="0.0075"/>
      </geometry>
      <origin rpy="0 0 0" xyz="0 0 0"/>
      <material name="black"/>
    </visual>
  </link>
  <link name="wheel_300deg_roller_6">
    <visual>
      <geometry>
        <cylinder length="0.022" radius="0.0075"/>
      </geometry>
      <origin rpy="0 0 0" xyz="0 0 0"/>
      <material name="black"/>
    </visual>
  </link>
  <link name="wheel_300deg_roller_7">
    <visual>
      <geometry>
        <cylinder length="0.022" radius="0.0075"/>
      </geometry>
      <origin rpy="0 0 0" xyz="0 0 0"/>
      <material name="black"/>
    </visual>
  </link>
  <link name="wheel_300deg_roller_8">
    <visual>
      <geometry>
        <cylinder length="0.022" radius="0.0075"/>
      </geometry>
      <origin rpy="0 0 0" xyz="0 0 0"/>
      <material name="black"/>
    </visual>
  </link>
  <link name="wheel_300deg_roller_9">
    <visual>
      <geometry>
        <cylinder length="0.022" radius="0.0075"/>
      </geometry>
      <origin rpy="0 0 0" xyz="0 0 0"/>
      <material name="black"/>
    </visual>
  </link>
  <link name="wheel_300deg_roller_10">
    <visual>
      <geometry>
        <cylinder length="0.022" radius="0.0075"/>
      </geometry>
      <origin rpy="0 0 0" xyz="0 0 0"/>
      <material name="black"/>
    </visual>
  </link>
  <link name="wheel_300deg_roller_11">
    <visual>
      <geometry>
        <cylinder length="0.022" radius="0.0075"/>
      </geometry>
      <origin rpy="0 0 0" xyz="0 0 0"/>
      <material name="black"/>
    </visual>
  </link>
  <link name="wheel_300deg_roller_12">
    <visual>
      <geometry>
        <cylinder length="0.022" radius="0.0075"/>
      </geometry>
      <origin rpy="0 0 0" xyz="0 0 0"/>
      <material name="black"/>
    </visual>
  </link>
  <joint name="base_wheel300_joint" type="continuous">
    <parent link="base_link"/>
    <child link="wheel_300deg"/>
    <axis xyz="0 0 1"/>
    <origin rpy="0 1.5707963267948966 3.141592653589793" xyz="-0.12 0.0 0"/>
  </joint>
  <joint name="wheel_300deg_roller_1" type="continuous">
    <parent link="wheel_300deg"/>
    <child link="wheel_300deg_roller_1"/>
    <axis xyz="0 0 1"/>
    <origin rpy="1.5707963267948966 0 0" xyz="0.035 0 0"/>
  </joint>
  <joint name="wheel_300deg_roller_2" type="continuous">
    <parent link="wheel_300deg"/>
    <child link="wheel_300deg_roller_2"/>
    <axis xyz="0 0 1"/>
    <origin rpy="1.5707963267948966 0 0" xyz="-0.035 0 0"/>
  </joint>
  <joint name="wheel_300deg_roller_3" type="continuous">
    <parent link="wheel_300deg"/>
    <child link="wheel_300deg_roller_3"/>
    <axis xyz="0 0 1"/>
    <origin rpy="1.5707963267948966 0 -1.0471975511965976" xyz="-0.0175 0.03 0"/>
  </joint>
  <joint name="wheel_300deg_roller_4" type="continuous">
    <parent link="wheel_300deg"/>
    <child link="wheel_300deg_roller_4"/>
    <axis xyz="0 0 1"/>
    <origin rpy="1.5707963267948966 0 -1.0471975511965976" xyz="0.0175 -0.03 0"/>
  </joint>
  <joint name="wheel_300deg_roller_5" type="continuous">
    <parent link="wheel_300deg"/>
    <child link="wheel_300deg_roller_5"/>
    <axis xyz="0 0 1"/>
    <origin rpy="1.5707963267948966 0 1.0471975511965976" xyz="-0.0175 -0.03 0"/>
  </joint>
  <joint name="wheel_300deg_roller_6" type="continuous">
    <parent link="wheel_300deg"/>
    <child link="wheel_300deg_roller_6"/>
    <axis xyz="0 0 1"/>
    <origin rpy="1.5707963267948966 0 1.0471975511965976" xyz="0.0175 0.03 0"/>
  </joint>
  <joint name="wheel_300deg_roller_7" type="continuous">
    <parent link="wheel_300deg"/>
    <child link="wheel_300deg_roller_7"/>
    <axis xyz="0 0 1"/>
    <origin rpy="1.5707963267948966 0 1.5707963267948966" xyz="0 0.035 0.03"/>
  </joint>
  <joint name="wheel_300deg_roller_8" type="continuous">
    <parent link="wheel_300deg"/>
    <child link="wheel_300deg_roller_8"/>
    <axis xyz="0 0 1"/>
    <origin rpy="1.5707963267948966 0 1.5707963267948966" xyz="0 -0.035 0.03"/>
  </joint>
  <joint name="wheel_300deg_roller_9" type="continuous">
    <parent link="wheel_300deg"/>
    <child link="wheel_300deg_roller_9"/>
    <axis xyz="0 0 1"/>
    <origin rpy="1.5707963267948966 0 0.57" xyz="-0.03 -0.0175 0.03"/>
  </joint>
  <joint name="wheel_300deg_roller_10" type="continuous">
    <parent link="wheel_300deg"/>
    <child link="wheel_300deg_roller_10"/>
    <axis xyz="0 0 1"/>
    <origin rpy="1.5707963267948966 0 0.57" xyz="0.03 0.0175 0.03"/>
  </joint>
  <joint name="wheel_300deg_roller_11" type="continuous">
    <parent link="wheel_300deg"/>
    <child link="wheel_300deg_roller_11"/>
    <axis xyz="0 0 1"/>
    <origin rpy="1.5707963267948966 0 -0.57" xyz="-0.03 0.0175 0.03"/>
  </joint>
  <joint name="wheel_300deg_roller_12" type="continuous">
    <parent link="wheel_300deg"/>
    <child link="wheel_300deg_roller_12"/>
    <axis xyz="0 0 1"/>
    <origin rpy="1.5707963267948966 0 -0.57" xyz="0.03 -0.0175 0.03"/>
  </joint>
  <!--Wheel 180deg-->
  <link name="wheel_180deg">
    <visual>
      <geometry>
        <cylinder length="0.03" radius="0.035"/>
      </geometry>
      <origin rpy="0 0 0" xyz="0 0 0.015"/>
      <material name="green"/>
    </visual>
  </link>
  <link name="wheel_180deg_roller_1">
    <visual>
      <geometry>
        <cylinder length="0.022" radius="0.0075"/>
      </geometry>
      <origin rpy="0 0 0" xyz="0 0 0"/>
      <material name="black"/>
    </visual>
  </link>
  <link name="wheel_180deg_roller_2">
    <visual>
      <geometry>
        <cylinder length="0.022" radius="0.0075"/>
      </geometry>
      <origin rpy="0 0 0" xyz="0 0 0"/>
      <material name="black"/>
    </visual>
  </link>
  <link name="wheel_180deg_roller_3">
    <visual>
      <geometry>
        <cylinder length="0.022" radius="0.0075"/>
      </geometry>
      <origin rpy="0 0 0" xyz="0 0 0"/>
      <material name="black"/>
    </visual>
  </link>
  <link name="wheel_180deg_roller_4">
    <visual>
      <geometry>
        <cylinder length="0.022" radius="0.0075"/>
      </geometry>
      <origin rpy="0 0 0" xyz="0 0 0"/>
      <material name="black"/>
    </visual>
  </link>
  <link name="wheel_180deg_roller_5">
    <visual>
      <geometry>
        <cylinder length="0.022" radius="0.0075"/>
      </geometry>
      <origin rpy="0 0 0" xyz="0 0 0"/>
      <material name="black"/>
    </visual>
  </link>
  <link name="wheel_180deg_roller_6">
    <visual>
      <geometry>
        <cylinder length="0.022" radius="0.0075"/>
      </geometry>
      <origin rpy="0 0 0" xyz="0 0 0"/>
      <material name="black"/>
    </visual>
  </link>
  <link name="wheel_180deg_roller_7">
    <visual>
      <geometry>
        <cylinder length="0.022" radius="0.0075"/>
      </geometry>
      <origin rpy="0 0 0" xyz="0 0 0"/>
      <material name="black"/>
    </visual>
  </link>
  <link name="wheel_180deg_roller_8">
    <visual>
      <geometry>
        <cylinder length="0.022" radius="0.0075"/>
      </geometry>
      <origin rpy="0 0 0" xyz="0 0 0"/>
      <material name="black"/>
    </visual>
  </link>
  <link name="wheel_180deg_roller_9">
    <visual>
      <geometry>
        <cylinder length="0.022" radius="0.0075"/>
      </geometry>
      <origin rpy="0 0 0" xyz="0 0 0"/>
      <material name="black"/>
    </visual>
  </link>
  <link name="wheel_180deg_roller_10">
    <visual>
      <geometry>
        <cylinder length="0.022" radius="0.0075"/>
      </geometry>
      <origin rpy="0 0 0" xyz="0 0 0"/>
      <material name="black"/>
    </visual>
  </link>
  <link name="wheel_180deg_roller_11">
    <visual>
      <geometry>
        <cylinder length="0.022" radius="0.0075"/>
      </geometry>
      <origin rpy="0 0 0" xyz="0 0 0"/>
      <material name="black"/>
    </visual>
  </link>
  <link name="wheel_180deg_roller_12">
    <visual>
      <geometry>
        <cylinder length="0.022" radius="0.0075"/>
      </geometry>
      <origin rpy="0 0 0" xyz="0 0 0"/>
      <material name="black"/>
    </visual>
  </link>
  <joint name="base_wheel180_joint" type="continuous">
    <parent link="base_link"/>
    <child link="wheel_180deg"/>
    <axis xyz="0 0 1"/>
    <origin rpy="1.04 1.5707963267948966 0" xyz="0.06 -0.10392304845413262 0"/>
  </joint>
  <joint name="wheel_180deg_roller_1" type="continuous">
    <parent link="wheel_180deg"/>
    <child link="wheel_180deg_roller_1"/>
    <axis xyz="0 0 1"/>
    <origin rpy="1.5707963267948966 0 0" xyz="0.035 0 0"/>
  </joint>
  <joint name="wheel_180deg_roller_2" type="continuous">
    <parent link="wheel_180deg"/>
    <child link="wheel_180deg_roller_2"/>
    <axis xyz="0 0 1"/>
    <origin rpy="1.5707963267948966 0 0" xyz="-0.035 0 0"/>
  </joint>
  <joint name="wheel_180deg_roller_3" type="continuous">
    <parent link="wheel_180deg"/>
    <child link="wheel_180deg_roller_3"/>
    <axis xyz="0 0 1"/>
    <origin rpy="1.5707963267948966 0 -1.0471975511965976" xyz="-0.0175 0.03 0"/>
  </joint>
  <joint name="wheel_180deg_roller_4" type="continuous">
    <parent link="wheel_180deg"/>
    <child link="wheel_180deg_roller_4"/>
    <axis xyz="0 0 1"/>
    <origin rpy="1.5707963267948966 0 -1.0471975511965976" xyz="0.0175 -0.03 0"/>
  </joint>
  <joint name="wheel_180deg_roller_5" type="continuous">
    <parent link="wheel_180deg"/>
    <child link="wheel_180deg_roller_5"/>
    <axis xyz="0 0 1"/>
    <origin rpy="1.5707963267948966 0 1.0471975511965976" xyz="-0.0175 -0.03 0"/>
  </joint>
  <joint name="wheel_180deg_roller_6" type="continuous">
    <parent link="wheel_180deg"/>
    <child link="wheel_180deg_roller_6"/>
    <axis xyz="0 0 1"/>
    <origin rpy="1.5707963267948966 0 1.0471975511965976" xyz="0.0175 0.03 0"/>
  </joint>
  <joint name="wheel_180deg_roller_7" type="continuous">
    <parent link="wheel_180deg"/>
    <child link="wheel_180deg_roller_7"/>
    <axis xyz="0 0 1"/>
    <origin rpy="1.5707963267948966 0 1.5707963267948966" xyz="0 0.035 0.03"/>
  </joint>
  <joint name="wheel_180deg_roller_8" type="continuous">
    <parent link="wheel_180deg"/>
    <child link="wheel_180deg_roller_8"/>
    <axis xyz="0 0 1"/>
    <origin rpy="1.5707963267948966 0 1.5707963267948966" xyz="0 -0.035 0.03"/>
  </joint>
  <joint name="wheel_180deg_roller_9" type="continuous">
    <parent link="wheel_180deg"/>
    <child link="wheel_180deg_roller_9"/>
    <axis xyz="0 0 1"/>
    <origin rpy="1.5707963267948966 0 0.57" xyz="-0.03 -0.0175 0.03"/>
  </joint>
  <joint name="wheel_180deg_roller_10" type="continuous">
    <parent link="wheel_180deg"/>
    <child link="wheel_180deg_roller_10"/>
    <axis xyz="0 0 1"/>
    <origin rpy="1.5707963267948966 0 0.57" xyz="0.03 0.0175 0.03"/>
  </joint>
  <joint name="wheel_180deg_roller_11" type="continuous">
    <parent link="wheel_180deg"/>
    <child link="wheel_180deg_roller_11"/>
    <axis xyz="0 0 1"/>
    <origin rpy="1.5707963267948966 0 -0.57" xyz="-0.03 0.0175 0.03"/>
  </joint>
  <joint name="wheel_180deg_roller_12" type="continuous">
    <parent link="wheel_180deg"/>
    <child link="wheel_180deg_roller_12"/>
    <axis xyz="0 0 1"/>
    <origin rpy="1.5707963267948966 0 -0.57" xyz="0.03 -0.0175 0.03"/>
  </joint>
</robot>
