<?xml version="1.0" ?>
<!-- =================================================================================== -->
<!-- |    This document was autogenerated by xacro from humblebot.xacro                | -->
<!-- |    EDITING THIS FILE BY HAND IS NOT RECOMMENDED                                 | -->
<!-- =================================================================================== -->
<robot name="humblebot">
  <!-- Common Properties -->
  <!-- colors-->
  <material name="green">
    <color rgba="0 1 0 1"/>
  </material>
  <material name="black">
    <color rgba="0 0 0 1"/>
  </material>
  <!-- Inertia -->
  <!-- Mobile Base -->
  <!-- Calculated/Constant variables -->
  <!-- macros -->
  <!-- Base link -->
  <link name="base_footprint"/>
  <link name="base_link">
    <visual>
      <geometry>
        <cylinder length="0.08" radius="0.12"/>
      </geometry>
      <origin rpy="0 0 0" xyz="0 0 0.04"/>
      <material name="green"/>
    </visual>
    <collision>
      <geometry>
        <cylinder length="0.08" radius="0.12"/>
      </geometry>
      <origin rpy="0 0 0" xyz="0 0 0.04"/>
    </collision>
    <inertial>
      <origin rpy="0 0 0" xyz="0 0 0.04"/>
      <mass value="0.3"/>
      <inertia ixx="0.0012399999999999998" ixy="0.0" ixz="0.0" iyy="0.0012399999999999998" iyz="0.0" izz="0.0021599999999999996"/>
    </inertial>
  </link>
  <!--Wheel 60deg links-->
  <link name="wheel_60deg">
    <visual>
      <geometry>
        <cylinder length="0.03" radius="0.035"/>
      </geometry>
      <origin rpy="0 0 0" xyz="0 0 0.015"/>
      <material name="green"/>
    </visual>
    <collision>
      <geometry>
        <cylinder length="0.03" radius="0.035"/>
      </geometry>
      <origin rpy="0 0 0" xyz="0 0 0.015"/>
    </collision>
    <inertial>
      <origin rpy="0 0 0" xyz="0 0 0.015"/>
      <mass value="0.02"/>
      <inertia ixx="7.625000000000001e-06" ixy="0.0" ixz="0.0" iyy="7.625000000000001e-06" iyz="0.0" izz="1.2250000000000003e-05"/>
    </inertial>
  </link>
  <link name="wheel_60deg_roller_1">
    <visual>
      <geometry>
        <cylinder length="0.022" radius="0.0075"/>
      </geometry>
      <origin rpy="0 0 0" xyz="0 0 0"/>
      <material name="black"/>
    </visual>
    <collision>
      <geometry>
        <cylinder length="0.022" radius="0.0075"/>
      </geometry>
      <origin rpy="0 0 0" xyz="0 0 0"/>
    </collision>
    <inertial>
      <origin rpy="0 0 0" xyz="0 0 0"/>
      <mass value="0.003"/>
      <inertia ixx="1.6318749999999998e-07" ixy="0.0" ixz="0.0" iyy="1.6318749999999998e-07" iyz="0.0" izz="8.437499999999999e-08"/>
    </inertial>
  </link>
  <link name="wheel_60deg_roller_2">
    <visual>
      <geometry>
        <cylinder length="0.022" radius="0.0075"/>
      </geometry>
      <origin rpy="0 0 0" xyz="0 0 0"/>
      <material name="black"/>
    </visual>
    <collision>
      <geometry>
        <cylinder length="0.022" radius="0.0075"/>
      </geometry>
      <origin rpy="0 0 0" xyz="0 0 0"/>
    </collision>
    <inertial>
      <origin rpy="0 0 0" xyz="0 0 0"/>
      <mass value="0.003"/>
      <inertia ixx="1.6318749999999998e-07" ixy="0.0" ixz="0.0" iyy="1.6318749999999998e-07" iyz="0.0" izz="8.437499999999999e-08"/>
    </inertial>
  </link>
  <link name="wheel_60deg_roller_3">
    <visual>
      <geometry>
        <cylinder length="0.022" radius="0.0075"/>
      </geometry>
      <origin rpy="0 0 0" xyz="0 0 0"/>
      <material name="black"/>
    </visual>
    <collision>
      <geometry>
        <cylinder length="0.022" radius="0.0075"/>
      </geometry>
      <origin rpy="0 0 0" xyz="0 0 0"/>
    </collision>
    <inertial>
      <origin rpy="0 0 0" xyz="0 0 0"/>
      <mass value="0.003"/>
      <inertia ixx="1.6318749999999998e-07" ixy="0.0" ixz="0.0" iyy="1.6318749999999998e-07" iyz="0.0" izz="8.437499999999999e-08"/>
    </inertial>
  </link>
  <link name="wheel_60deg_roller_4">
    <visual>
      <geometry>
        <cylinder length="0.022" radius="0.0075"/>
      </geometry>
      <origin rpy="0 0 0" xyz="0 0 0"/>
      <material name="black"/>
    </visual>
    <collision>
      <geometry>
        <cylinder length="0.022" radius="0.0075"/>
      </geometry>
      <origin rpy="0 0 0" xyz="0 0 0"/>
    </collision>
    <inertial>
      <origin rpy="0 0 0" xyz="0 0 0"/>
      <mass value="0.003"/>
      <inertia ixx="1.6318749999999998e-07" ixy="0.0" ixz="0.0" iyy="1.6318749999999998e-07" iyz="0.0" izz="8.437499999999999e-08"/>
    </inertial>
  </link>
  <link name="wheel_60deg_roller_5">
    <visual>
      <geometry>
        <cylinder length="0.022" radius="0.0075"/>
      </geometry>
      <origin rpy="0 0 0" xyz="0 0 0"/>
      <material name="black"/>
    </visual>
    <collision>
      <geometry>
        <cylinder length="0.022" radius="0.0075"/>
      </geometry>
      <origin rpy="0 0 0" xyz="0 0 0"/>
    </collision>
    <inertial>
      <origin rpy="0 0 0" xyz="0 0 0"/>
      <mass value="0.003"/>
      <inertia ixx="1.6318749999999998e-07" ixy="0.0" ixz="0.0" iyy="1.6318749999999998e-07" iyz="0.0" izz="8.437499999999999e-08"/>
    </inertial>
  </link>
  <link name="wheel_60deg_roller_6">
    <visual>
      <geometry>
        <cylinder length="0.022" radius="0.0075"/>
      </geometry>
      <origin rpy="0 0 0" xyz="0 0 0"/>
      <material name="black"/>
    </visual>
    <collision>
      <geometry>
        <cylinder length="0.022" radius="0.0075"/>
      </geometry>
      <origin rpy="0 0 0" xyz="0 0 0"/>
    </collision>
    <inertial>
      <origin rpy="0 0 0" xyz="0 0 0"/>
      <mass value="0.003"/>
      <inertia ixx="1.6318749999999998e-07" ixy="0.0" ixz="0.0" iyy="1.6318749999999998e-07" iyz="0.0" izz="8.437499999999999e-08"/>
    </inertial>
  </link>
  <link name="wheel_60deg_roller_7">
    <visual>
      <geometry>
        <cylinder length="0.022" radius="0.0075"/>
      </geometry>
      <origin rpy="0 0 0" xyz="0 0 0"/>
      <material name="black"/>
    </visual>
    <collision>
      <geometry>
        <cylinder length="0.022" radius="0.0075"/>
      </geometry>
      <origin rpy="0 0 0" xyz="0 0 0"/>
    </collision>
    <inertial>
      <origin rpy="0 0 0" xyz="0 0 0"/>
      <mass value="0.003"/>
      <inertia ixx="1.6318749999999998e-07" ixy="0.0" ixz="0.0" iyy="1.6318749999999998e-07" iyz="0.0" izz="8.437499999999999e-08"/>
    </inertial>
  </link>
  <link name="wheel_60deg_roller_8">
    <visual>
      <geometry>
        <cylinder length="0.022" radius="0.0075"/>
      </geometry>
      <origin rpy="0 0 0" xyz="0 0 0"/>
      <material name="black"/>
    </visual>
    <collision>
      <geometry>
        <cylinder length="0.022" radius="0.0075"/>
      </geometry>
      <origin rpy="0 0 0" xyz="0 0 0"/>
    </collision>
    <inertial>
      <origin rpy="0 0 0" xyz="0 0 0"/>
      <mass value="0.003"/>
      <inertia ixx="1.6318749999999998e-07" ixy="0.0" ixz="0.0" iyy="1.6318749999999998e-07" iyz="0.0" izz="8.437499999999999e-08"/>
    </inertial>
  </link>
  <link name="wheel_60deg_roller_9">
    <visual>
      <geometry>
        <cylinder length="0.022" radius="0.0075"/>
      </geometry>
      <origin rpy="0 0 0" xyz="0 0 0"/>
      <material name="black"/>
    </visual>
    <collision>
      <geometry>
        <cylinder length="0.022" radius="0.0075"/>
      </geometry>
      <origin rpy="0 0 0" xyz="0 0 0"/>
    </collision>
    <inertial>
      <origin rpy="0 0 0" xyz="0 0 0"/>
      <mass value="0.003"/>
      <inertia ixx="1.6318749999999998e-07" ixy="0.0" ixz="0.0" iyy="1.6318749999999998e-07" iyz="0.0" izz="8.437499999999999e-08"/>
    </inertial>
  </link>
  <link name="wheel_60deg_roller_10">
    <visual>
      <geometry>
        <cylinder length="0.022" radius="0.0075"/>
      </geometry>
      <origin rpy="0 0 0" xyz="0 0 0"/>
      <material name="black"/>
    </visual>
    <collision>
      <geometry>
        <cylinder length="0.022" radius="0.0075"/>
      </geometry>
      <origin rpy="0 0 0" xyz="0 0 0"/>
    </collision>
    <inertial>
      <origin rpy="0 0 0" xyz="0 0 0"/>
      <mass value="0.003"/>
      <inertia ixx="1.6318749999999998e-07" ixy="0.0" ixz="0.0" iyy="1.6318749999999998e-07" iyz="0.0" izz="8.437499999999999e-08"/>
    </inertial>
  </link>
  <link name="wheel_60deg_roller_11">
    <visual>
      <geometry>
        <cylinder length="0.022" radius="0.0075"/>
      </geometry>
      <origin rpy="0 0 0" xyz="0 0 0"/>
      <material name="black"/>
    </visual>
    <collision>
      <geometry>
        <cylinder length="0.022" radius="0.0075"/>
      </geometry>
      <origin rpy="0 0 0" xyz="0 0 0"/>
    </collision>
    <inertial>
      <origin rpy="0 0 0" xyz="0 0 0"/>
      <mass value="0.003"/>
      <inertia ixx="1.6318749999999998e-07" ixy="0.0" ixz="0.0" iyy="1.6318749999999998e-07" iyz="0.0" izz="8.437499999999999e-08"/>
    </inertial>
  </link>
  <link name="wheel_60deg_roller_12">
    <visual>
      <geometry>
        <cylinder length="0.022" radius="0.0075"/>
      </geometry>
      <origin rpy="0 0 0" xyz="0 0 0"/>
      <material name="black"/>
    </visual>
    <collision>
      <geometry>
        <cylinder length="0.022" radius="0.0075"/>
      </geometry>
      <origin rpy="0 0 0" xyz="0 0 0"/>
    </collision>
    <inertial>
      <origin rpy="0 0 0" xyz="0 0 0"/>
      <mass value="0.003"/>
      <inertia ixx="1.6318749999999998e-07" ixy="0.0" ixz="0.0" iyy="1.6318749999999998e-07" iyz="0.0" izz="8.437499999999999e-08"/>
    </inertial>
  </link>
  <!--Wheel 300deg links-->
  <link name="wheel_300deg">
    <visual>
      <geometry>
        <cylinder length="0.03" radius="0.035"/>
      </geometry>
      <origin rpy="0 0 0" xyz="0 0 0.015"/>
      <material name="green"/>
    </visual>
    <collision>
      <geometry>
        <cylinder length="0.03" radius="0.035"/>
      </geometry>
      <origin rpy="0 0 0" xyz="0 0 0.015"/>
    </collision>
    <inertial>
      <origin rpy="0 0 0" xyz="0 0 0.015"/>
      <mass value="0.02"/>
      <inertia ixx="7.625000000000001e-06" ixy="0.0" ixz="0.0" iyy="7.625000000000001e-06" iyz="0.0" izz="1.2250000000000003e-05"/>
    </inertial>
  </link>
  <link name="wheel_300deg_roller_1">
    <visual>
      <geometry>
        <cylinder length="0.022" radius="0.0075"/>
      </geometry>
      <origin rpy="0 0 0" xyz="0 0 0"/>
      <material name="black"/>
    </visual>
    <collision>
      <geometry>
        <cylinder length="0.022" radius="0.0075"/>
      </geometry>
      <origin rpy="0 0 0" xyz="0 0 0"/>
    </collision>
    <inertial>
      <origin rpy="0 0 0" xyz="0 0 0"/>
      <mass value="0.003"/>
      <inertia ixx="1.6318749999999998e-07" ixy="0.0" ixz="0.0" iyy="1.6318749999999998e-07" iyz="0.0" izz="8.437499999999999e-08"/>
    </inertial>
  </link>
  <link name="wheel_300deg_roller_2">
    <visual>
      <geometry>
        <cylinder length="0.022" radius="0.0075"/>
      </geometry>
      <origin rpy="0 0 0" xyz="0 0 0"/>
      <material name="black"/>
    </visual>
    <collision>
      <geometry>
        <cylinder length="0.022" radius="0.0075"/>
      </geometry>
      <origin rpy="0 0 0" xyz="0 0 0"/>
    </collision>
    <inertial>
      <origin rpy="0 0 0" xyz="0 0 0"/>
      <mass value="0.003"/>
      <inertia ixx="1.6318749999999998e-07" ixy="0.0" ixz="0.0" iyy="1.6318749999999998e-07" iyz="0.0" izz="8.437499999999999e-08"/>
    </inertial>
  </link>
  <link name="wheel_300deg_roller_3">
    <visual>
      <geometry>
        <cylinder length="0.022" radius="0.0075"/>
      </geometry>
      <origin rpy="0 0 0" xyz="0 0 0"/>
      <material name="black"/>
    </visual>
    <collision>
      <geometry>
        <cylinder length="0.022" radius="0.0075"/>
      </geometry>
      <origin rpy="0 0 0" xyz="0 0 0"/>
    </collision>
    <inertial>
      <origin rpy="0 0 0" xyz="0 0 0"/>
      <mass value="0.003"/>
      <inertia ixx="1.6318749999999998e-07" ixy="0.0" ixz="0.0" iyy="1.6318749999999998e-07" iyz="0.0" izz="8.437499999999999e-08"/>
    </inertial>
  </link>
  <link name="wheel_300deg_roller_4">
    <visual>
      <geometry>
        <cylinder length="0.022" radius="0.0075"/>
      </geometry>
      <origin rpy="0 0 0" xyz="0 0 0"/>
      <material name="black"/>
    </visual>
    <collision>
      <geometry>
        <cylinder length="0.022" radius="0.0075"/>
      </geometry>
      <origin rpy="0 0 0" xyz="0 0 0"/>
    </collision>
    <inertial>
      <origin rpy="0 0 0" xyz="0 0 0"/>
      <mass value="0.003"/>
      <inertia ixx="1.6318749999999998e-07" ixy="0.0" ixz="0.0" iyy="1.6318749999999998e-07" iyz="0.0" izz="8.437499999999999e-08"/>
    </inertial>
  </link>
  <link name="wheel_300deg_roller_5">
    <visual>
      <geometry>
        <cylinder length="0.022" radius="0.0075"/>
      </geometry>
      <origin rpy="0 0 0" xyz="0 0 0"/>
      <material name="black"/>
    </visual>
    <collision>
      <geometry>
        <cylinder length="0.022" radius="0.0075"/>
      </geometry>
      <origin rpy="0 0 0" xyz="0 0 0"/>
    </collision>
    <inertial>
      <origin rpy="0 0 0" xyz="0 0 0"/>
      <mass value="0.003"/>
      <inertia ixx="1.6318749999999998e-07" ixy="0.0" ixz="0.0" iyy="1.6318749999999998e-07" iyz="0.0" izz="8.437499999999999e-08"/>
    </inertial>
  </link>
  <link name="wheel_300deg_roller_6">
    <visual>
      <geometry>
        <cylinder length="0.022" radius="0.0075"/>
      </geometry>
      <origin rpy="0 0 0" xyz="0 0 0"/>
      <material name="black"/>
    </visual>
    <collision>
      <geometry>
        <cylinder length="0.022" radius="0.0075"/>
      </geometry>
      <origin rpy="0 0 0" xyz="0 0 0"/>
    </collision>
    <inertial>
      <origin rpy="0 0 0" xyz="0 0 0"/>
      <mass value="0.003"/>
      <inertia ixx="1.6318749999999998e-07" ixy="0.0" ixz="0.0" iyy="1.6318749999999998e-07" iyz="0.0" izz="8.437499999999999e-08"/>
    </inertial>
  </link>
  <link name="wheel_300deg_roller_7">
    <visual>
      <geometry>
        <cylinder length="0.022" radius="0.0075"/>
      </geometry>
      <origin rpy="0 0 0" xyz="0 0 0"/>
      <material name="black"/>
    </visual>
    <collision>
      <geometry>
        <cylinder length="0.022" radius="0.0075"/>
      </geometry>
      <origin rpy="0 0 0" xyz="0 0 0"/>
    </collision>
    <inertial>
      <origin rpy="0 0 0" xyz="0 0 0"/>
      <mass value="0.003"/>
      <inertia ixx="1.6318749999999998e-07" ixy="0.0" ixz="0.0" iyy="1.6318749999999998e-07" iyz="0.0" izz="8.437499999999999e-08"/>
    </inertial>
  </link>
  <link name="wheel_300deg_roller_8">
    <visual>
      <geometry>
        <cylinder length="0.022" radius="0.0075"/>
      </geometry>
      <origin rpy="0 0 0" xyz="0 0 0"/>
      <material name="black"/>
    </visual>
    <collision>
      <geometry>
        <cylinder length="0.022" radius="0.0075"/>
      </geometry>
      <origin rpy="0 0 0" xyz="0 0 0"/>
    </collision>
    <inertial>
      <origin rpy="0 0 0" xyz="0 0 0"/>
      <mass value="0.003"/>
      <inertia ixx="1.6318749999999998e-07" ixy="0.0" ixz="0.0" iyy="1.6318749999999998e-07" iyz="0.0" izz="8.437499999999999e-08"/>
    </inertial>
  </link>
  <link name="wheel_300deg_roller_9">
    <visual>
      <geometry>
        <cylinder length="0.022" radius="0.0075"/>
      </geometry>
      <origin rpy="0 0 0" xyz="0 0 0"/>
      <material name="black"/>
    </visual>
    <collision>
      <geometry>
        <cylinder length="0.022" radius="0.0075"/>
      </geometry>
      <origin rpy="0 0 0" xyz="0 0 0"/>
    </collision>
    <inertial>
      <origin rpy="0 0 0" xyz="0 0 0"/>
      <mass value="0.003"/>
      <inertia ixx="1.6318749999999998e-07" ixy="0.0" ixz="0.0" iyy="1.6318749999999998e-07" iyz="0.0" izz="8.437499999999999e-08"/>
    </inertial>
  </link>
  <link name="wheel_300deg_roller_10">
    <visual>
      <geometry>
        <cylinder length="0.022" radius="0.0075"/>
      </geometry>
      <origin rpy="0 0 0" xyz="0 0 0"/>
      <material name="black"/>
    </visual>
    <collision>
      <geometry>
        <cylinder length="0.022" radius="0.0075"/>
      </geometry>
      <origin rpy="0 0 0" xyz="0 0 0"/>
    </collision>
    <inertial>
      <origin rpy="0 0 0" xyz="0 0 0"/>
      <mass value="0.003"/>
      <inertia ixx="1.6318749999999998e-07" ixy="0.0" ixz="0.0" iyy="1.6318749999999998e-07" iyz="0.0" izz="8.437499999999999e-08"/>
    </inertial>
  </link>
  <link name="wheel_300deg_roller_11">
    <visual>
      <geometry>
        <cylinder length="0.022" radius="0.0075"/>
      </geometry>
      <origin rpy="0 0 0" xyz="0 0 0"/>
      <material name="black"/>
    </visual>
    <collision>
      <geometry>
        <cylinder length="0.022" radius="0.0075"/>
      </geometry>
      <origin rpy="0 0 0" xyz="0 0 0"/>
    </collision>
    <inertial>
      <origin rpy="0 0 0" xyz="0 0 0"/>
      <mass value="0.003"/>
      <inertia ixx="1.6318749999999998e-07" ixy="0.0" ixz="0.0" iyy="1.6318749999999998e-07" iyz="0.0" izz="8.437499999999999e-08"/>
    </inertial>
  </link>
  <link name="wheel_300deg_roller_12">
    <visual>
      <geometry>
        <cylinder length="0.022" radius="0.0075"/>
      </geometry>
      <origin rpy="0 0 0" xyz="0 0 0"/>
      <material name="black"/>
    </visual>
    <collision>
      <geometry>
        <cylinder length="0.022" radius="0.0075"/>
      </geometry>
      <origin rpy="0 0 0" xyz="0 0 0"/>
    </collision>
    <inertial>
      <origin rpy="0 0 0" xyz="0 0 0"/>
      <mass value="0.003"/>
      <inertia ixx="1.6318749999999998e-07" ixy="0.0" ixz="0.0" iyy="1.6318749999999998e-07" iyz="0.0" izz="8.437499999999999e-08"/>
    </inertial>
  </link>
  <!--Wheel 180deg links-->
  <link name="wheel_180deg">
    <visual>
      <geometry>
        <cylinder length="0.03" radius="0.035"/>
      </geometry>
      <origin rpy="0 0 0" xyz="0 0 0.015"/>
      <material name="green"/>
    </visual>
    <collision>
      <geometry>
        <cylinder length="0.03" radius="0.035"/>
      </geometry>
      <origin rpy="0 0 0" xyz="0 0 0.015"/>
    </collision>
    <inertial>
      <origin rpy="0 0 0" xyz="0 0 0.015"/>
      <mass value="0.02"/>
      <inertia ixx="7.625000000000001e-06" ixy="0.0" ixz="0.0" iyy="7.625000000000001e-06" iyz="0.0" izz="1.2250000000000003e-05"/>
    </inertial>
  </link>
  <link name="wheel_180deg_roller_1">
    <visual>
      <geometry>
        <cylinder length="0.022" radius="0.0075"/>
      </geometry>
      <origin rpy="0 0 0" xyz="0 0 0"/>
      <material name="black"/>
    </visual>
    <collision>
      <geometry>
        <cylinder length="0.022" radius="0.0075"/>
      </geometry>
      <origin rpy="0 0 0" xyz="0 0 0"/>
    </collision>
    <inertial>
      <origin rpy="0 0 0" xyz="0 0 0"/>
      <mass value="0.003"/>
      <inertia ixx="1.6318749999999998e-07" ixy="0.0" ixz="0.0" iyy="1.6318749999999998e-07" iyz="0.0" izz="8.437499999999999e-08"/>
    </inertial>
  </link>
  <link name="wheel_180deg_roller_2">
    <visual>
      <geometry>
        <cylinder length="0.022" radius="0.0075"/>
      </geometry>
      <origin rpy="0 0 0" xyz="0 0 0"/>
      <material name="black"/>
    </visual>
    <collision>
      <geometry>
        <cylinder length="0.022" radius="0.0075"/>
      </geometry>
      <origin rpy="0 0 0" xyz="0 0 0"/>
    </collision>
    <inertial>
      <origin rpy="0 0 0" xyz="0 0 0"/>
      <mass value="0.003"/>
      <inertia ixx="1.6318749999999998e-07" ixy="0.0" ixz="0.0" iyy="1.6318749999999998e-07" iyz="0.0" izz="8.437499999999999e-08"/>
    </inertial>
  </link>
  <link name="wheel_180deg_roller_3">
    <visual>
      <geometry>
        <cylinder length="0.022" radius="0.0075"/>
      </geometry>
      <origin rpy="0 0 0" xyz="0 0 0"/>
      <material name="black"/>
    </visual>
    <collision>
      <geometry>
        <cylinder length="0.022" radius="0.0075"/>
      </geometry>
      <origin rpy="0 0 0" xyz="0 0 0"/>
    </collision>
    <inertial>
      <origin rpy="0 0 0" xyz="0 0 0"/>
      <mass value="0.003"/>
      <inertia ixx="1.6318749999999998e-07" ixy="0.0" ixz="0.0" iyy="1.6318749999999998e-07" iyz="0.0" izz="8.437499999999999e-08"/>
    </inertial>
  </link>
  <link name="wheel_180deg_roller_4">
    <visual>
      <geometry>
        <cylinder length="0.022" radius="0.0075"/>
      </geometry>
      <origin rpy="0 0 0" xyz="0 0 0"/>
      <material name="black"/>
    </visual>
    <collision>
      <geometry>
        <cylinder length="0.022" radius="0.0075"/>
      </geometry>
      <origin rpy="0 0 0" xyz="0 0 0"/>
    </collision>
    <inertial>
      <origin rpy="0 0 0" xyz="0 0 0"/>
      <mass value="0.003"/>
      <inertia ixx="1.6318749999999998e-07" ixy="0.0" ixz="0.0" iyy="1.6318749999999998e-07" iyz="0.0" izz="8.437499999999999e-08"/>
    </inertial>
  </link>
  <link name="wheel_180deg_roller_5">
    <visual>
      <geometry>
        <cylinder length="0.022" radius="0.0075"/>
      </geometry>
      <origin rpy="0 0 0" xyz="0 0 0"/>
      <material name="black"/>
    </visual>
    <collision>
      <geometry>
        <cylinder length="0.022" radius="0.0075"/>
      </geometry>
      <origin rpy="0 0 0" xyz="0 0 0"/>
    </collision>
    <inertial>
      <origin rpy="0 0 0" xyz="0 0 0"/>
      <mass value="0.003"/>
      <inertia ixx="1.6318749999999998e-07" ixy="0.0" ixz="0.0" iyy="1.6318749999999998e-07" iyz="0.0" izz="8.437499999999999e-08"/>
    </inertial>
  </link>
  <link name="wheel_180deg_roller_6">
    <visual>
      <geometry>
        <cylinder length="0.022" radius="0.0075"/>
      </geometry>
      <origin rpy="0 0 0" xyz="0 0 0"/>
      <material name="black"/>
    </visual>
    <collision>
      <geometry>
        <cylinder length="0.022" radius="0.0075"/>
      </geometry>
      <origin rpy="0 0 0" xyz="0 0 0"/>
    </collision>
    <inertial>
      <origin rpy="0 0 0" xyz="0 0 0"/>
      <mass value="0.003"/>
      <inertia ixx="1.6318749999999998e-07" ixy="0.0" ixz="0.0" iyy="1.6318749999999998e-07" iyz="0.0" izz="8.437499999999999e-08"/>
    </inertial>
  </link>
  <link name="wheel_180deg_roller_7">
    <visual>
      <geometry>
        <cylinder length="0.022" radius="0.0075"/>
      </geometry>
      <origin rpy="0 0 0" xyz="0 0 0"/>
      <material name="black"/>
    </visual>
    <collision>
      <geometry>
        <cylinder length="0.022" radius="0.0075"/>
      </geometry>
      <origin rpy="0 0 0" xyz="0 0 0"/>
    </collision>
    <inertial>
      <origin rpy="0 0 0" xyz="0 0 0"/>
      <mass value="0.003"/>
      <inertia ixx="1.6318749999999998e-07" ixy="0.0" ixz="0.0" iyy="1.6318749999999998e-07" iyz="0.0" izz="8.437499999999999e-08"/>
    </inertial>
  </link>
  <link name="wheel_180deg_roller_8">
    <visual>
      <geometry>
        <cylinder length="0.022" radius="0.0075"/>
      </geometry>
      <origin rpy="0 0 0" xyz="0 0 0"/>
      <material name="black"/>
    </visual>
    <collision>
      <geometry>
        <cylinder length="0.022" radius="0.0075"/>
      </geometry>
      <origin rpy="0 0 0" xyz="0 0 0"/>
    </collision>
    <inertial>
      <origin rpy="0 0 0" xyz="0 0 0"/>
      <mass value="0.003"/>
      <inertia ixx="1.6318749999999998e-07" ixy="0.0" ixz="0.0" iyy="1.6318749999999998e-07" iyz="0.0" izz="8.437499999999999e-08"/>
    </inertial>
  </link>
  <link name="wheel_180deg_roller_9">
    <visual>
      <geometry>
        <cylinder length="0.022" radius="0.0075"/>
      </geometry>
      <origin rpy="0 0 0" xyz="0 0 0"/>
      <material name="black"/>
    </visual>
    <collision>
      <geometry>
        <cylinder length="0.022" radius="0.0075"/>
      </geometry>
      <origin rpy="0 0 0" xyz="0 0 0"/>
    </collision>
    <inertial>
      <origin rpy="0 0 0" xyz="0 0 0"/>
      <mass value="0.003"/>
      <inertia ixx="1.6318749999999998e-07" ixy="0.0" ixz="0.0" iyy="1.6318749999999998e-07" iyz="0.0" izz="8.437499999999999e-08"/>
    </inertial>
  </link>
  <link name="wheel_180deg_roller_10">
    <visual>
      <geometry>
        <cylinder length="0.022" radius="0.0075"/>
      </geometry>
      <origin rpy="0 0 0" xyz="0 0 0"/>
      <material name="black"/>
    </visual>
    <collision>
      <geometry>
        <cylinder length="0.022" radius="0.0075"/>
      </geometry>
      <origin rpy="0 0 0" xyz="0 0 0"/>
    </collision>
    <inertial>
      <origin rpy="0 0 0" xyz="0 0 0"/>
      <mass value="0.003"/>
      <inertia ixx="1.6318749999999998e-07" ixy="0.0" ixz="0.0" iyy="1.6318749999999998e-07" iyz="0.0" izz="8.437499999999999e-08"/>
    </inertial>
  </link>
  <link name="wheel_180deg_roller_11">
    <visual>
      <geometry>
        <cylinder length="0.022" radius="0.0075"/>
      </geometry>
      <origin rpy="0 0 0" xyz="0 0 0"/>
      <material name="black"/>
    </visual>
    <collision>
      <geometry>
        <cylinder length="0.022" radius="0.0075"/>
      </geometry>
      <origin rpy="0 0 0" xyz="0 0 0"/>
    </collision>
    <inertial>
      <origin rpy="0 0 0" xyz="0 0 0"/>
      <mass value="0.003"/>
      <inertia ixx="1.6318749999999998e-07" ixy="0.0" ixz="0.0" iyy="1.6318749999999998e-07" iyz="0.0" izz="8.437499999999999e-08"/>
    </inertial>
  </link>
  <link name="wheel_180deg_roller_12">
    <visual>
      <geometry>
        <cylinder length="0.022" radius="0.0075"/>
      </geometry>
      <origin rpy="0 0 0" xyz="0 0 0"/>
      <material name="black"/>
    </visual>
    <collision>
      <geometry>
        <cylinder length="0.022" radius="0.0075"/>
      </geometry>
      <origin rpy="0 0 0" xyz="0 0 0"/>
    </collision>
    <inertial>
      <origin rpy="0 0 0" xyz="0 0 0"/>
      <mass value="0.003"/>
      <inertia ixx="1.6318749999999998e-07" ixy="0.0" ixz="0.0" iyy="1.6318749999999998e-07" iyz="0.0" izz="8.437499999999999e-08"/>
    </inertial>
  </link>
  <!--Wheel 60deg joints-->
  <joint name="base_joint" type="fixed">
    <parent link="base_footprint"/>
    <child link="base_link"/>
    <origin rpy="0 0 0" xyz="0 0 0.035"/>
  </joint>
  <joint name="base_wheel60_joint" type="continuous">
    <parent link="base_link"/>
    <child link="wheel_60deg"/>
    <axis xyz="0 0 1"/>
    <origin rpy="-1.0471975511965976 1.5707963267948966 0" xyz="0.06 0.10392304845413262 0"/>
  </joint>
  <joint name="wheel_60deg_roller_1_joint" type="continuous">
    <parent link="wheel_60deg"/>
    <child link="wheel_60deg_roller_1"/>
    <axis xyz="0 0 1"/>
    <origin rpy="1.5707963267948966 0 0" xyz="0.035 0 0"/>
  </joint>
  <joint name="wheel_60deg_roller_2_joint" type="continuous">
    <parent link="wheel_60deg"/>
    <child link="wheel_60deg_roller_2"/>
    <axis xyz="0 0 1"/>
    <origin rpy="1.5707963267948966 0 0" xyz="-0.035 0 0"/>
  </joint>
  <joint name="wheel_60deg_roller_3_joint" type="continuous">
    <parent link="wheel_60deg"/>
    <child link="wheel_60deg_roller_3"/>
    <axis xyz="0 0 1"/>
    <origin rpy="1.5707963267948966 0 -1.0471975511965976" xyz="-0.0175 0.03 0"/>
  </joint>
  <joint name="wheel_60deg_roller_4_joint" type="continuous">
    <parent link="wheel_60deg"/>
    <child link="wheel_60deg_roller_4"/>
    <axis xyz="0 0 1"/>
    <origin rpy="1.5707963267948966 0 -1.0471975511965976" xyz="0.0175 -0.03 0"/>
  </joint>
  <joint name="wheel_60deg_roller_5_joint" type="continuous">
    <parent link="wheel_60deg"/>
    <child link="wheel_60deg_roller_5"/>
    <axis xyz="0 0 1"/>
    <origin rpy="1.5707963267948966 0 1.0471975511965976" xyz="-0.0175 -0.03 0"/>
  </joint>
  <joint name="wheel_60deg_roller_6_joint" type="continuous">
    <parent link="wheel_60deg"/>
    <child link="wheel_60deg_roller_6"/>
    <axis xyz="0 0 1"/>
    <origin rpy="1.5707963267948966 0 1.0471975511965976" xyz="0.0175 0.03 0"/>
  </joint>
  <joint name="wheel_60deg_roller_7_joint" type="continuous">
    <parent link="wheel_60deg"/>
    <child link="wheel_60deg_roller_7"/>
    <axis xyz="0 0 1"/>
    <origin rpy="1.5707963267948966 0 1.5707963267948966" xyz="0 0.035 0.03"/>
  </joint>
  <joint name="wheel_60deg_roller_8_joint" type="continuous">
    <parent link="wheel_60deg"/>
    <child link="wheel_60deg_roller_8"/>
    <axis xyz="0 0 1"/>
    <origin rpy="1.5707963267948966 0 1.5707963267948966" xyz="0 -0.035 0.03"/>
  </joint>
  <joint name="wheel_60deg_roller_9_joint" type="continuous">
    <parent link="wheel_60deg"/>
    <child link="wheel_60deg_roller_9"/>
    <axis xyz="0 0 1"/>
    <origin rpy="1.5707963267948966 0 0.57" xyz="-0.03 -0.0175 0.03"/>
  </joint>
  <joint name="wheel_60deg_roller_10_joint" type="continuous">
    <parent link="wheel_60deg"/>
    <child link="wheel_60deg_roller_10"/>
    <axis xyz="0 0 1"/>
    <origin rpy="1.5707963267948966 0 0.57" xyz="0.03 0.0175 0.03"/>
  </joint>
  <joint name="wheel_60deg_roller_11_joint" type="continuous">
    <parent link="wheel_60deg"/>
    <child link="wheel_60deg_roller_11"/>
    <axis xyz="0 0 1"/>
    <origin rpy="1.5707963267948966 0 -0.57" xyz="-0.03 0.0175 0.03"/>
  </joint>
  <joint name="wheel_60deg_roller_12_joint" type="continuous">
    <parent link="wheel_60deg"/>
    <child link="wheel_60deg_roller_12"/>
    <axis xyz="0 0 1"/>
    <origin rpy="1.5707963267948966 0 -0.57" xyz="0.03 -0.0175 0.03"/>
  </joint>
  <!--Wheel 300deg joints-->
  <joint name="base_wheel300_joint" type="continuous">
    <parent link="base_link"/>
    <child link="wheel_300deg"/>
    <axis xyz="0 0 1"/>
    <origin rpy="0 1.5707963267948966 3.141592653589793" xyz="-0.12 0.0 0"/>
  </joint>
  <joint name="wheel_300deg_roller_1_joint" type="continuous">
    <parent link="wheel_300deg"/>
    <child link="wheel_300deg_roller_1"/>
    <axis xyz="0 0 1"/>
    <origin rpy="1.5707963267948966 0 0" xyz="0.035 0 0"/>
  </joint>
  <joint name="wheel_300deg_roller_2_joint" type="continuous">
    <parent link="wheel_300deg"/>
    <child link="wheel_300deg_roller_2"/>
    <axis xyz="0 0 1"/>
    <origin rpy="1.5707963267948966 0 0" xyz="-0.035 0 0"/>
  </joint>
  <joint name="wheel_300deg_roller_3_joint" type="continuous">
    <parent link="wheel_300deg"/>
    <child link="wheel_300deg_roller_3"/>
    <axis xyz="0 0 1"/>
    <origin rpy="1.5707963267948966 0 -1.0471975511965976" xyz="-0.0175 0.03 0"/>
  </joint>
  <joint name="wheel_300deg_roller_4_joint" type="continuous">
    <parent link="wheel_300deg"/>
    <child link="wheel_300deg_roller_4"/>
    <axis xyz="0 0 1"/>
    <origin rpy="1.5707963267948966 0 -1.0471975511965976" xyz="0.0175 -0.03 0"/>
  </joint>
  <joint name="wheel_300deg_roller_5_joint" type="continuous">
    <parent link="wheel_300deg"/>
    <child link="wheel_300deg_roller_5"/>
    <axis xyz="0 0 1"/>
    <origin rpy="1.5707963267948966 0 1.0471975511965976" xyz="-0.0175 -0.03 0"/>
  </joint>
  <joint name="wheel_300deg_roller_6_joint" type="continuous">
    <parent link="wheel_300deg"/>
    <child link="wheel_300deg_roller_6"/>
    <axis xyz="0 0 1"/>
    <origin rpy="1.5707963267948966 0 1.0471975511965976" xyz="0.0175 0.03 0"/>
  </joint>
  <joint name="wheel_300deg_roller_7_joint" type="continuous">
    <parent link="wheel_300deg"/>
    <child link="wheel_300deg_roller_7"/>
    <axis xyz="0 0 1"/>
    <origin rpy="1.5707963267948966 0 1.5707963267948966" xyz="0 0.035 0.03"/>
  </joint>
  <joint name="wheel_300deg_roller_8_joint" type="continuous">
    <parent link="wheel_300deg"/>
    <child link="wheel_300deg_roller_8"/>
    <axis xyz="0 0 1"/>
    <origin rpy="1.5707963267948966 0 1.5707963267948966" xyz="0 -0.035 0.03"/>
  </joint>
  <joint name="wheel_300deg_roller_9_joint" type="continuous">
    <parent link="wheel_300deg"/>
    <child link="wheel_300deg_roller_9"/>
    <axis xyz="0 0 1"/>
    <origin rpy="1.5707963267948966 0 0.57" xyz="-0.03 -0.0175 0.03"/>
  </joint>
  <joint name="wheel_300deg_roller_10_joint" type="continuous">
    <parent link="wheel_300deg"/>
    <child link="wheel_300deg_roller_10"/>
    <axis xyz="0 0 1"/>
    <origin rpy="1.5707963267948966 0 0.57" xyz="0.03 0.0175 0.03"/>
  </joint>
  <joint name="wheel_300deg_roller_11_joint" type="continuous">
    <parent link="wheel_300deg"/>
    <child link="wheel_300deg_roller_11"/>
    <axis xyz="0 0 1"/>
    <origin rpy="1.5707963267948966 0 -0.57" xyz="-0.03 0.0175 0.03"/>
  </joint>
  <joint name="wheel_300deg_roller_12_joint" type="continuous">
    <parent link="wheel_300deg"/>
    <child link="wheel_300deg_roller_12"/>
    <axis xyz="0 0 1"/>
    <origin rpy="1.5707963267948966 0 -0.57" xyz="0.03 -0.0175 0.03"/>
  </joint>
  <!--Wheel 180deg joints-->
  <joint name="base_wheel180_joint" type="continuous">
    <parent link="base_link"/>
    <child link="wheel_180deg"/>
    <axis xyz="0 0 1"/>
    <origin rpy="1.04 1.5707963267948966 0" xyz="0.06 -0.10392304845413262 0"/>
  </joint>
  <joint name="wheel_180deg_roller_1_joint" type="continuous">
    <parent link="wheel_180deg"/>
    <child link="wheel_180deg_roller_1"/>
    <axis xyz="0 0 1"/>
    <origin rpy="1.5707963267948966 0 0" xyz="0.035 0 0"/>
  </joint>
  <joint name="wheel_180deg_roller_2_joint" type="continuous">
    <parent link="wheel_180deg"/>
    <child link="wheel_180deg_roller_2"/>
    <axis xyz="0 0 1"/>
    <origin rpy="1.5707963267948966 0 0" xyz="-0.035 0 0"/>
  </joint>
  <joint name="wheel_180deg_roller_3_joint" type="continuous">
    <parent link="wheel_180deg"/>
    <child link="wheel_180deg_roller_3"/>
    <axis xyz="0 0 1"/>
    <origin rpy="1.5707963267948966 0 -1.0471975511965976" xyz="-0.0175 0.03 0"/>
  </joint>
  <joint name="wheel_180deg_roller_4_joint" type="continuous">
    <parent link="wheel_180deg"/>
    <child link="wheel_180deg_roller_4"/>
    <axis xyz="0 0 1"/>
    <origin rpy="1.5707963267948966 0 -1.0471975511965976" xyz="0.0175 -0.03 0"/>
  </joint>
  <joint name="wheel_180deg_roller_5_joint" type="continuous">
    <parent link="wheel_180deg"/>
    <child link="wheel_180deg_roller_5"/>
    <axis xyz="0 0 1"/>
    <origin rpy="1.5707963267948966 0 1.0471975511965976" xyz="-0.0175 -0.03 0"/>
  </joint>
  <joint name="wheel_180deg_roller_6_joint" type="continuous">
    <parent link="wheel_180deg"/>
    <child link="wheel_180deg_roller_6"/>
    <axis xyz="0 0 1"/>
    <origin rpy="1.5707963267948966 0 1.0471975511965976" xyz="0.0175 0.03 0"/>
  </joint>
  <joint name="wheel_180deg_roller_7_joint" type="continuous">
    <parent link="wheel_180deg"/>
    <child link="wheel_180deg_roller_7"/>
    <axis xyz="0 0 1"/>
    <origin rpy="1.5707963267948966 0 1.5707963267948966" xyz="0 0.035 0.03"/>
  </joint>
  <joint name="wheel_180deg_roller_8_joint" type="continuous">
    <parent link="wheel_180deg"/>
    <child link="wheel_180deg_roller_8"/>
    <axis xyz="0 0 1"/>
    <origin rpy="1.5707963267948966 0 1.5707963267948966" xyz="0 -0.035 0.03"/>
  </joint>
  <joint name="wheel_180deg_roller_9_joint" type="continuous">
    <parent link="wheel_180deg"/>
    <child link="wheel_180deg_roller_9"/>
    <axis xyz="0 0 1"/>
    <origin rpy="1.5707963267948966 0 0.57" xyz="-0.03 -0.0175 0.03"/>
  </joint>
  <joint name="wheel_180deg_roller_10_joint" type="continuous">
    <parent link="wheel_180deg"/>
    <child link="wheel_180deg_roller_10"/>
    <axis xyz="0 0 1"/>
    <origin rpy="1.5707963267948966 0 0.57" xyz="0.03 0.0175 0.03"/>
  </joint>
  <joint name="wheel_180deg_roller_11_joint" type="continuous">
    <parent link="wheel_180deg"/>
    <child link="wheel_180deg_roller_11"/>
    <axis xyz="0 0 1"/>
    <origin rpy="1.5707963267948966 0 -0.57" xyz="-0.03 0.0175 0.03"/>
  </joint>
  <joint name="wheel_180deg_roller_12_joint" type="continuous">
    <parent link="wheel_180deg"/>
    <child link="wheel_180deg_roller_12"/>
    <axis xyz="0 0 1"/>
    <origin rpy="1.5707963267948966 0 -0.57" xyz="0.03 -0.0175 0.03"/>
  </joint>
</robot>
